Workbook

Sheet Note

Sheet 1010
C3: Dư nợ update tới 10/09 | G3: N.o | H3: =COLUMN(H3)-COLUMN($H$3)+1 -> 1 | I3: =COLUMN(I3)-COLUMN($H$3)+1 -> 2 | J3: =COLUMN(J3)-COLUMN($H$3)+1 -> 3 | K3: =COLUMN(K3)-COLUMN($H$3)+1 -> 4 | L3: =COLUMN(L3)-COLUMN($H$3)+1 -> 5 | M3: =COLUMN(M3)-COLUMN($H$3)+1 -> 6 | N3: =COLUMN(N3)-COLUMN($H$3)+1 -> 7
G5: Tổng kết dư nợ
G6: Cách thức: Ai có dòng màu đỏ "Chuyển tiền" chuyển khoản hết cho t theo "Tổng tiền" tương ứng phía trên, xong t sẽ chuyển lại cho những người có dòng màu xanh "Nhận tiền".
C7: Summary số lượng
C8: Số người | D8: Nội dung | G8: Thành viên | H8: Toàn | I8: Trường + Thủy | J8: Băng + Tâm | K8: Tú | L8: Kiên | M8: Tạ Ánh | N8: Quân
C9: 8 | D9: Đánh cầu 10/10 | G9: =C22 -> Tổng ứng trước | H9: =round(sumif($D:$D,H8,$C:$C),0) -> 571667 | I9: =round(sumif($D:$D,I8,$C:$C),0) -> 85000 | J9: =round(sumif($D:$D,J8,$C:$C),0) -> 0 | K9: =round(sumif($D:$D,K8,$C:$C),0) -> 0 | L9: =round(sumif($D:$D,L8,$C:$C),0) -> 60000 | M9: =round(sumif($D:$D,M8,$C:$C),0) -> 0 | N9: =round(sumif($D:$D,N8,$C:$C),0) -> 0
C10: 7 | D10: Đánh cầu 03/10 | G10: ="[-] "&G22 -> [-] Tổng chi phí | H10: =round(sum(H26:H30),0) -> 47381 | I10: =round(sum(I26:I30),0) -> 176012 | J10: =round(sum(J26:J30),0) -> 176012 | K10: =round(sum(K26:K30),0) -> 88006 | L10: =round(sum(L26:L30),0) -> 88006 | M10: =round(sum(M26:M30),0) -> 40625 | N10: =round(sum(N26:N30),0) -> 40625
G11: ="[-] "&G33 -> [-] Bù trừ nợ đợt trước | H11: =Sum(H35:H44) -> 65825 | I11: =Sum(I35:I44) -> 0 | J11: =Sum(J35:J44) -> 0 | K11: =Sum(K35:K44) -> 217397 | L11: =Sum(L35:L44) -> -283222 | M11: =Sum(M35:M44) -> 0 | N11: =Sum(N35:N44) -> 0
G12: Tổng tiền thanh toán | H12: =H9-H10-H11 -> 458461 | I12: =I9-I10-I11 -> -91012 | J12: =J9-J10-J11 -> -176012 | K12: =K9-K10-K11 -> -305403 | L12: =L9-L10-L11 -> 255216 | M12: =M9-M10-M11 -> -40625 | N12: =N9-N10-N11 -> -40625
G14: K/q | H14: =if(H12<0,"Chuyển tiền","Nhận tiền") -> Nhận tiền | I14: =if(I12<0,"Chuyển tiền","Nhận tiền") -> Chuyển tiền | J14: =if(J12<0,"Chuyển tiền","Nhận tiền") -> Chuyển tiền | K14: =if(K12<0,"Chuyển tiền","Nhận tiền") -> Chuyển tiền | L14: =if(L12<0,"Chuyển tiền","Nhận tiền") -> Nhận tiền | M14: =if(M12<0,"Chuyển tiền","Nhận tiền") -> Chuyển tiền | N14: =if(N12<0,"Chuyển tiền","Nhận tiền") -> Chuyển tiền
G16: Tình trạng thanh toán | H16: =-sum(I16:N16) -> -613052 | I16: =-I12 -> 91012 | J16: =-J12 -> 176012 | K16: =-K12 -> 305403 | M16: =-M12 -> 40625
G18: Dư nợ (>0: nhận lại) | H18: =H12+H16 -> -154591 | I18: =I12+I16 -> 0 | J18: =J12+J16 -> 0 | K18: =K12+K16 -> 0 | L18: =L12+L16 -> 255216 | M18: =M12+M16 -> 0 | N18: =N12+N16 -> -40625
G19: Status | H19: =IF(AND(H18>=-3000,H18<=1000), "Done", "") | I19: =IF(AND(I18>=-3000,I18<=1000), "Done", "") -> Done | J19: =IF(AND(J18>=-3000,J18<=1000), "Done", "") -> Done | K19: =IF(AND(K18>=-3000,K18<=1000), "Done", "") -> Done | L19: =IF(AND(L18>=-3000,L18<=1000), "Done", "") | M19: =IF(AND(M18>=-3000,M18<=1000), "Done", "") -> Done | N19: =IF(AND(N18>=-3000,N18<=1000), "Done", "")
C21: Nội dung chi tiết:
C22: Tổng ứng trước | G22: Tổng chi phí
C24: Tổng tiền | D24: Ứng bởi | E24: Ghi chú | F24: Check | G24: Danh mục chi tiêu | H24: =H8 -> Toàn | I24: =I8 -> Trường + Thủy | J24: =J8 -> Băng + Tâm | K24: =K8 -> Tú | L24: =L8 -> Kiên | M24: =M8 -> Tạ Ánh | N24: =N8 -> Quân | O24: Số người
G25: Đánh cầu ngày 10/10
C26: 240000 | D26: =H24 -> Toàn | E26: 1 sân | F26: =C26=sum(H26:N26) -> TRUE | G26: Tiền sân cầu lông 10/10 | I26: =$C26/$C$9*2 -> 60000 | J26: =$C26/$C$9*2 -> 60000 | K26: =$C26/$C$9 -> 30000 | L26: =$C26/$C$9 -> 30000 | M26: =$C26/$C$9 -> 30000 | N26: =$C26/$C$9 -> 30000 | O26: =COUNTIF(H26:N26,"<>0")+2 -> 8
C27: =340000/12*3 -> 85000 | D27: =I24 -> Trường + Thủy | E27: 340k ~ 12 quả | F27: =C27=sum(H27:N27) -> TRUE | G27: Tiền cầu (3 quả) 10/10 | I27: =$C27/$C$9*2 -> 21250 | J27: =$C27/$C$9*2 -> 21250 | K27: =$C27/$C$9 -> 10625 | L27: =$C27/$C$9 -> 10625 | M27: =$C27/$C$9 -> 10625 | N27: =$C27/$C$9 -> 10625 | O27: =COUNTIF(H27:N27,"<>0")+2 -> 8
G28: Đánh cầu ngày 03/10
C29: 190000 | D29: =D26 -> Toàn | E29: 1 sân | F29: =C29=sum(H29:N29) -> TRUE | G29: Tiền sân cầu lông 03/10 | H29: =$C29/$C$10 -> 27142.857 | I29: =$C29/$C$10*2 -> 54285.714 | J29: =$C29/$C$10*2 -> 54285.714 | K29: =$C29/$C$10 -> 27142.857 | L29: =$C29/$C$10 -> 27142.857 | O29: =COUNTIF(H29:N29,"<>0")+2 -> 7
C30: =340000/12*5 -> 141666.67 | D30: =D26 -> Toàn | E30: 340k ~ 12 quả | F30: =C30=sum(H30:N30) -> TRUE | G30: Tiền cầu (5 quả) 03/10 | H30: =$C30/$C$10 -> 20238.095 | I30: =$C30/$C$10*2 -> 40476.19 | J30: =$C30/$C$10*2 -> 40476.19 | K30: =$C30/$C$10 -> 20238.095 | L30: =$C30/$C$10 -> 20238.095 | O30: =COUNTIF(H30:N30,"<>0")+2 -> 7
C31: 60000 | D31: =L24 -> Kiên | E31: 10k ~ 1 chai | F31: =C31=sum(H31:N31) -> TRUE | G31: Revice + đá | H31: =$C31/$C$10 -> 8571.4286 | I31: =$C31/$C$10*2 -> 17142.857 | J31: =$C31/$C$10*2 -> 17142.857 | K31: =$C31/$C$10 -> 8571.4286 | L31: =$C31/$C$10 -> 8571.4286 | O31: =COUNTIF(H31:N31,"<>0")+2 -> 7
G33: Bù trừ nợ đợt trước
F35: =If(C35 - round(sum(H35:N35),0) < 5000, True, False) -> TRUE | G35: Tiền cầu lông 12/09 (xem sheet trc) | H35: {=-_xlfn.XLOOKUP(H$24,'2609'!$8:$8,'2609'!$18:$18)} -> 65825 | K35: {=-_xlfn.XLOOKUP(K$24,'2609'!$8:$8,'2609'!$18:$18)} -> 217397 | L35: {=-_xlfn.XLOOKUP(L$24,'2609'!$8:$8,'2609'!$18:$18)} -> -283222 | O35: =COUNTIF(H35:N35,"<>0") -> 3
F36: =If(C36 - round(sum(H36:N36),0) < 5000, True, False) -> TRUE | G36: Kiên, Toàn | Cơm rang gà MQ | H36: -35000 | L36: =-H36 -> 35000 | O36: =COUNTIF(H36:N36,"<>0") -> 2
F37: =If(C37 - round(sum(H37:N37),0) < 5000, True, False) -> TRUE | G37: Kiên, Toàn | Cơm trưa | H37: 35000 | L37: =-H37 -> -35000 | O37: =COUNTIF(H37:N37,"<>0") -> 2
C39: DETAILS

Sheet 2609
C3: Dư nợ update tới 26/09 | G3: N.o | H3: =COLUMN(H3)-COLUMN($H$3)+1 -> 1 | I3: =COLUMN(I3)-COLUMN($H$3)+1 -> 2 | J3: =COLUMN(J3)-COLUMN($H$3)+1 -> 3 | K3: =COLUMN(K3)-COLUMN($H$3)+1 -> 4 | L3: =COLUMN(L3)-COLUMN($H$3)+1 -> 5 | M3: =COLUMN(M3)-COLUMN($H$3)+1 -> 6 | N3: =COLUMN(N3)-COLUMN($H$3)+1 -> 7 | O3: =COLUMN(O3)-COLUMN($H$3)+1 -> 8 | ... Q3: =COLUMN(Q3)-COLUMN($H$3)+1 -> 10
G5: Tổng kết dư nợ
G6: Cách thức: Ai có dòng màu đỏ "Chuyển tiền" chuyển khoản hết cho t theo "Tổng tiền" tương ứng phía trên, xong t sẽ chuyển lại cho những người có dòng màu xanh "Nhận tiền".
C7: Summary số lượng | M7: Outs. | N7: Outs.
C8: Số người | D8: Nội dung | G8: Thành viên | H8: Toàn | I8: Trường + Thủy | J8: Băng + Tâm | K8: Tú | L8: Kiên | M8: Thái | N8: Thảo + Ny | O8: Diệp | P8: Châu Linh | Q8: Quân
C9: 13 | D9: Đánh cầu 19/09 | G9: =C22 -> Tổng ứng trước | H9: =round(sumif($D:$D,H8,$C:$C),0) -> 928333 | I9: =round(sumif($D:$D,I8,$C:$C),0) -> 0 | J9: =round(sumif($D:$D,J8,$C:$C),0) -> 0 | K9: =round(sumif($D:$D,K8,$C:$C),0) -> 0 | L9: =round(sumif($D:$D,L8,$C:$C),0) -> 60000 | M9: =round(sumif($D:$D,M8,$C:$C),0) -> 0 | N9: =round(sumif($D:$D,N8,$C:$C),0) -> 0 | O9: =round(sumif($D:$D,O8,$C:$C),0) -> 0 | ... Q9: =round(sumif($D:$D,Q8,$C:$C),0) -> 0
C10: 7 | D10: Đánh cầu 26/09 | G10: ="[-] "&G22 -> [-] Tổng chi phí | H10: =round(sum(H26:H31),0) -> 108355 | I10: =round(sum(I26:I31),0) -> 204711 | J10: =round(sum(J26:J31),0) -> 84615 | K10: =round(sum(K26:K31),0) -> 108355 | L10: =round(sum(L26:L31),0) -> 54308 | M10: =round(sum(M26:M31),0) -> 96355 | N10: =round(sum(N26:N31),0) -> 138663 | O10: =round(sum(O26:O31),0) -> 42308 | ... Q10: =round(sum(Q26:Q31),0) -> 54308
G11: ="[-] "&G33 -> [-] Bù trừ nợ đợt trước | H11: =Sum(H35:H44) -> -49595 | I11: =Sum(I35:I44) -> 218083 | J11: =Sum(J35:J44) -> 0 | K11: =Sum(K35:K44) -> 109042 | L11: =Sum(L35:L44) -> -277530 | M11: =Sum(M35:M44) -> 0 | N11: =Sum(N35:N44) -> 0 | O11: =Sum(O35:O44) -> 0 | ... Q11: =Sum(Q35:Q44) -> 0
G12: Tổng tiền thanh toán | H12: =H9-H10-H11 -> 869573 | I12: =I9-I10-I11 -> -422794 | J12: =J9-J10-J11 -> -84615 | K12: =K9-K10-K11 -> -217397 | L12: =L9-L10-L11 -> 283222 | M12: =M9-M10-M11 -> -96355 | N12: =N9-N10-N11 -> -138663 | O12: =O9-O10-O11 -> -42308 | ... Q12: =Q9-Q10-Q11 -> -54308
G14: K/q | H14: =if(H12<0,"Chuyển tiền","Nhận tiền") -> Nhận tiền | I14: =if(I12<0,"Chuyển tiền","Nhận tiền") -> Chuyển tiền | J14: =if(J12<0,"Chuyển tiền","Nhận tiền") -> Chuyển tiền | K14: =if(K12<0,"Chuyển tiền","Nhận tiền") -> Chuyển tiền | L14: =if(L12<0,"Chuyển tiền","Nhận tiền") -> Nhận tiền | M14: =if(M12<0,"Chuyển tiền","Nhận tiền") -> Chuyển tiền | N14: =if(N12<0,"Chuyển tiền","Nhận tiền") -> Chuyển tiền | O14: =if(O12<0,"Chuyển tiền","Nhận tiền") -> Chuyển tiền | ... Q14: =if(Q12<0,"Chuyển tiền","Nhận tiền") -> Chuyển tiền
G16: Tình trạng thanh toán | H16: =-sum(I16:Q16) -> -935398 | I16: =-I12 -> 422794 | J16: =-J12 -> 84615 | M16: =-M12 -> 96355 | N16: =-N12 -> 138663 | O16: =-O12 -> 42308 | P16: =-P12 -> 96355 | Q16: =-Q12 -> 54308
G18: Dư nợ (>0: nhận lại) | H18: =H12+H16 -> -65825 | I18: =I12+I16 -> 0 | J18: =J12+J16 -> 0 | K18: =K12+K16 -> -217397 | L18: =L12+L16 -> 283222 | M18: =M12+M16 -> 0 | N18: =N12+N16 -> 0 | O18: =O12+O16 -> 0 | ... Q18: =Q12+Q16 -> 0
G19: Status | H19: =IF(AND(H18>=-3000,H18<=1000), "Done", "") | I19: =IF(AND(I18>=-3000,I18<=1000), "Done", "") -> Done | J19: =IF(AND(J18>=-3000,J18<=1000), "Done", "") -> Done | K19: =IF(AND(K18>=-3000,K18<=1000), "Done", "") | L19: =IF(AND(L18>=-3000,L18<=1000), "Done", "") | M19: =IF(AND(M18>=-3000,M18<=2000), "Done", "") -> Done | N19: =IF(AND(N18>=-3000,N18<=2000), "Done", "") -> Done | O19: =IF(AND(O18>=-3000,O18<=2000), "Done", "") -> Done | P19: =IF(AND(P18>=-3000,P18<=1000), "Done", "") -> Done | Q19: =IF(AND(Q18>=-3000,Q18<=1000), "Done", "") -> Done
C21: Nội dung chi tiết:
C22: Tổng ứng trước | G22: Tổng chi phí
C24: Tổng tiền | D24: Ứng bởi | E24: Ghi chú | F24: Check | G24: Danh mục chi tiêu | H24: =H8 -> Toàn | I24: =I8 -> Trường + Thủy | J24: =J8 -> Băng + Tâm | K24: =K8 -> Tú | L24: =L8 -> Kiên | M24: =M8 -> Thái | N24: =N8 -> Thảo + Ny | O24: =O8 -> Diệp | ... Q24: =Q8 -> Quân | R24: Số người
G25: Đánh cầu ngày 19/09
C26: 380000 | D26: =H24 -> Toàn | E26: 2 sân | F26: =C26=sum(H26:Q26) -> TRUE | G26: Tiền sân cầu lông 19/09 | H26: =$C26/$C$9 -> 29230.769 | I26: =$C26/$C$9*2 -> 58461.538 | J26: =$C26/$C$9*2 -> 58461.538 | K26: =$C26/$C$9 -> 29230.769 | L26: =$C26/$C$9 -> 29230.769 | M26: =$C26/$C$9 -> 29230.769 | N26: =$C26/$C$9*2 -> 58461.538 | O26: =$C26/$C$9 -> 29230.769 | P26: =$C26/$C$9 -> 29230.769 | Q26: =$C26/$C$9 -> 29230.769 | R26: =COUNTIF(H26:Q26,"<>0")+3 -> 13
C27: =340000/12*6 -> 170000 | D27: =H24 -> Toàn | E27: 340k ~ 12 quả | F27: =C27=sum(H27:Q27) -> TRUE | G27: Tiền cầu (6 quả) 19/09 | H27: =$C27/$C$9 -> 13076.923 | I27: =$C27/$C$9*2 -> 26153.846 | J27: =$C27/$C$9*2 -> 26153.846 | K27: =$C27/$C$9 -> 13076.923 | L27: =$C27/$C$9 -> 13076.923 | M27: =$C27/$C$9 -> 13076.923 | N27: =$C27/$C$9*2 -> 26153.846 | O27: =$C27/$C$9 -> 13076.923 | P27: =$C27/$C$9 -> 13076.923 | Q27: =$C27/$C$9 -> 13076.923 | R27: =COUNTIF(H27:Q27,"<>0")+3 -> 13
C28: 60000 | D28: =L24 -> Kiên | F28: =C28=sum(H28:Q28) -> TRUE | G28: Tiền nước + đá | H28: =$C28/5 -> 12000 | I28: =$C28/5 -> 12000 | K28: =$C28/5 -> 12000 | L28: =$C28/5 -> 12000 | Q28: =$C28/5 -> 12000 | R28: =COUNTIF(H28:Q28,"<>0") -> 5
G29: Đánh cầu ngày 26/09
C30: 265000 | D30: =D26 -> Toàn | E30: 1 sân | F30: =C30=sum(H30:Q30) -> TRUE | G30: Tiền sân cầu lông 26/09 | H30: =$C30/$C$10 -> 37857.143 | I30: =$C30/$C$10*2 -> 75714.286 | K30: =$C30/$C$10 -> 37857.143 | M30: =$C30/$C$10 -> 37857.143 | N30: =$C30/$C$10 -> 37857.143 | P30: =$C30/$C$10 -> 37857.143 | R30: =COUNTIF(H30:Q30,"<>0")+1 -> 7
C31: =340000/12*4 -> 113333.33 | D31: =D26 -> Toàn | E31: 340k ~ 12 quả | F31: =C31=sum(H31:Q31) -> TRUE | G31: Tiền cầu (4 quả) 26/09 | H31: =$C31/$C$10 -> 16190.476 | I31: =$C31/$C$10*2 -> 32380.952 | K31: =$C31/$C$10 -> 16190.476 | M31: =$C31/$C$10 -> 16190.476 | N31: =$C31/$C$10 -> 16190.476 | P31: =$C31/$C$10 -> 16190.476 | R31: =COUNTIF(H31:Q31,"<>0")+1 -> 7
G33: Bù trừ nợ đợt trước
F35: =If(C35 - round(sum(H35:Q35),0) < 5000, True, False) -> TRUE | G35: Tiền cầu lông 12/09 (xem sheet trc) | H35: {=-_xlfn.XLOOKUP(H$24,'1209'!$8:$8,'1209'!$18:$18)} -> -37595 | I35: {=-_xlfn.XLOOKUP(I$24,'1209'!$8:$8,'1209'!$18:$18)} -> 218083 | K35: {=-_xlfn.XLOOKUP(K$24,'1209'!$8:$8,'1209'!$18:$18)} -> 109042 | L35: {=-_xlfn.XLOOKUP(L$24,'1209'!$8:$8,'1209'!$18:$18)} -> -289530 | R35: =COUNTIF(H35:Q35,"<>0") -> 4
F36: =If(C36 - round(sum(H36:Q36),0) < 5000, True, False) -> TRUE | G36: Kiên, Toàn | Mỳ gà tần | H36: -65000 | L36: =-H36 -> 65000 | R36: =COUNTIF(H36:Q36,"<>0") -> 2
F37: =If(C37 - round(sum(H37:Q37),0) < 5000, True, False) -> TRUE | G37: Kiên, Toàn | Bún riêu cua | H37: 53000 | L37: =-H37 -> -53000 | R37: =COUNTIF(H37:Q37,"<>0") -> 2
C39: DETAILS

Sheet 1209
C3: Dư nợ update tới 12/09 | G3: N.o | H3: =COLUMN(H3)-COLUMN($H$3)+1 -> 1 | I3: =COLUMN(I3)-COLUMN($H$3)+1 -> 2 | J3: =COLUMN(J3)-COLUMN($H$3)+1 -> 3 | K3: =COLUMN(K3)-COLUMN($H$3)+1 -> 4 | L3: =COLUMN(L3)-COLUMN($H$3)+1 -> 5 | M3: =COLUMN(M3)-COLUMN($H$3)+1 -> 6 | N3: =COLUMN(N3)-COLUMN($H$3)+1 -> 7 | O3: =COLUMN(O3)-COLUMN($H$3)+1 -> 8 | ... Q3: =COLUMN(Q3)-COLUMN($H$3)+1 -> 10
G5: Tổng kết dư nợ
G6: Cách thức: Ai có dòng màu đỏ "Chuyển tiền" chuyển khoản hết cho t theo "Tổng tiền" tương ứng phía trên, xong t sẽ chuyển lại cho những người có dòng màu xanh "Nhận tiền".
C7: Summary số lượng | M7: Outs. | N7: Outs. | O7: Outs.
C8: Số người | D8: Nội dung | G8: Thành viên | H8: Toàn | I8: Trường + Thủy | J8: Băng + Tâm | K8: Tú | L8: Kiên | M8: Thái | N8: Thảo | O8: Phan | P8: Châu Linh | Q8: Ngân
C9: 10 | D9: Đánh cầu 12/09 | G9: =C22 -> Tổng ứng trước | H9: =round(sumif($D:$D,H8,$C:$C),0) -> 826667 | I9: =round(sumif($D:$D,I8,$C:$C),0) -> 0 | J9: =round(sumif($D:$D,J8,$C:$C),0) -> 0 | K9: =round(sumif($D:$D,K8,$C:$C),0) -> 0 | L9: =round(sumif($D:$D,L8,$C:$C),0) -> 445000 | M9: =round(sumif($D:$D,M8,$C:$C),0) -> 0 | N9: =round(sumif($D:$D,N8,$C:$C),0) -> 0 | O9: =round(sumif($D:$D,O8,$C:$C),0) -> 50000 | ... Q9: =round(sumif($D:$D,Q8,$C:$C),0) -> 0
C10: 7 | D10: Đánh cầu 05/09 | G10: ="[-] "&G22 -> [-] Tổng chi phí | H10: =round(sum(H26:H34),0) -> 155470 | I10: =round(sum(I26:I34),0) -> 218083 | J10: =round(sum(J26:J34),0) -> 217190 | K10: =round(sum(K26:K34),0) -> 109042 | L10: =round(sum(L26:L34),0) -> 155470 | M10: =round(sum(M26:M34),0) -> 109042 | N10: =round(sum(N26:N34),0) -> 155470 | O10: =round(sum(O26:O34),0) -> 62167 | ... Q10: =round(sum(Q26:Q34),0) -> 46429
C11: 8 | D11: Đánh cầu 22/08 | G11: ="[-] "&G36 -> [-] Bù trừ nợ đợt trước | H11: =Sum(H38:H46) -> 0 | I11: =Sum(I38:I46) -> 0 | J11: =Sum(J38:J46) -> 0 | K11: =Sum(K38:K46) -> 0 | L11: =Sum(L38:L46) -> 0 | M11: =Sum(M38:M46) -> 0 | N11: =Sum(N38:N46) -> 0 | O11: =Sum(O38:O46) -> 0 | ... Q11: =Sum(Q38:Q46) -> 0
G12: Tổng tiền thanh toán | H12: =H9-H10-H11 -> 671197 | I12: =I9-I10-I11 -> -218083 | J12: =J9-J10-J11 -> -217190 | K12: =K9-K10-K11 -> -109042 | L12: =L9-L10-L11 -> 289530 | M12: =M9-M10-M11 -> -109042 | N12: =N9-N10-N11 -> -155470 | O12: =O9-O10-O11 -> -12167 | ... Q12: =Q9-Q10-Q11 -> -46429
G14: K/q | H14: =if(H12<0,"Chuyển tiền","Nhận tiền") -> Nhận tiền | I14: =if(I12<0,"Chuyển tiền","Nhận tiền") -> Chuyển tiền | J14: =if(J12<0,"Chuyển tiền","Nhận tiền") -> Chuyển tiền | K14: =if(K12<0,"Chuyển tiền","Nhận tiền") -> Chuyển tiền | L14: =if(L12<0,"Chuyển tiền","Nhận tiền") -> Nhận tiền | M14: =if(M12<0,"Chuyển tiền","Nhận tiền") -> Chuyển tiền | N14: =if(N12<0,"Chuyển tiền","Nhận tiền") -> Chuyển tiền | O14: =if(O12<0,"Chuyển tiền","Nhận tiền") -> Chuyển tiền | ... Q14: =if(Q12<0,"Chuyển tiền","Nhận tiền") -> Chuyển tiền
G16: Tình trạng thanh toán | H16: =-sum(I16:Q16) -> -633602 | J16: =-J12 -> 217190 | M16: =-M12 -> 109042 | N16: =-N12 -> 155470 | O16: =-O12 -> 12167 | P16: =-P12 -> 93304 | Q16: =-Q12 -> 46429
G18: Dư nợ (>0: nhận lại) | H18: =H12+H16 -> 37595 | I18: =I12+I16 -> -218083 | J18: =J12+J16 -> 0 | K18: =K12+K16 -> -109042 | L18: =L12+L16 -> 289530 | M18: =M12+M16 -> 0 | N18: =N12+N16 -> 0 | O18: =O12+O16 -> 0 | ... Q18: =Q12+Q16 -> 0
G19: Status | H19: =IF(AND(H18>=-3000,H18<=1000), "Done", "") | I19: =IF(AND(I18>=-3000,I18<=1000), "Done", "") | J19: =IF(AND(J18>=-3000,J18<=1000), "Done", "") -> Done | K19: =IF(AND(K18>=-3000,K18<=1000), "Done", "") | L19: =IF(AND(L18>=-3000,L18<=1000), "Done", "") | M19: =IF(AND(M18>=-3000,M18<=2000), "Done", "") -> Done | N19: =IF(AND(N18>=-3000,N18<=2000), "Done", "") -> Done | O19: =IF(AND(O18>=-3000,O18<=2000), "Done", "") -> Done | P19: =IF(AND(P18>=-3000,P18<=1000), "Done", "") -> Done | Q19: =IF(AND(Q18>=-3000,Q18<=1000), "Done", "") -> Done
C21: Nội dung chi tiết:
C22: Tổng ứng trước | G22: Tổng chi phí
C24: Tổng tiền | D24: Ứng bởi | E24: Ghi chú | F24: Check | G24: Danh mục chi tiêu | H24: =H8 -> Toàn | I24: =I8 -> Trường + Thủy | J24: =J8 -> Băng + Tâm | K24: =K8 -> Tú | L24: =L8 -> Kiên | M24: =M8 -> Thái | N24: =N8 -> Thảo | O24: =O8 -> Phan | ... Q24: =Q8 -> Ngân | R24: Số người
G25: Đánh cầu ngày 12/09
C26: =265000+80000 -> 345000 | D26: =H24 -> Toàn | F26: =C26=sum(H26:Q26) -> TRUE | G26: Tiền sân cầu lông 12/09 | H26: =$C26/$C$9 -> 34500 | I26: =$C26/$C$9*2 -> 69000 | J26: =$C26/$C$9*2 -> 69000 | K26: =$C26/$C$9 -> 34500 | L26: =$C26/$C$9 -> 34500 | M26: =$C26/$C$9 -> 34500 | N26: =$C26/$C$9 -> 34500 | O26: =$C26/$C$9 -> 34500 | R26: =COUNTIF(H26:Q26,"<>0")+2 -> 10
C27: =340000/12*8 -> 226666.67 | D27: =H24 -> Toàn | E27: 340k ~ 12 quả | F27: =C27=sum(H27:Q27) -> TRUE | G27: Tiền cầu (8 quả) 12/09 | H27: =$C27/$C$9 -> 22666.667 | I27: =$C27/$C$9*2 -> 45333.333 | J27: =$C27/$C$9*2 -> 45333.333 | K27: =$C27/$C$9 -> 22666.667 | L27: =$C27/$C$9 -> 22666.667 | M27: =$C27/$C$9 -> 22666.667 | N27: =$C27/$C$9 -> 22666.667 | O27: =$C27/$C$9 -> 22666.667 | R27: =COUNTIF(H27:Q27,"<>0")+2 -> 10
C28: 50000 | D28: =O24 -> Phan | F28: =C28=sum(H28:Q28) -> TRUE | G28: Trà đá (2 can) | H28: =$C28/$C$9 -> 5000 | I28: =$C28/$C$9*2 -> 10000 | J28: =$C28/$C$9*2 -> 10000 | K28: =$C28/$C$9 -> 5000 | L28: =$C28/$C$9 -> 5000 | M28: =$C28/$C$9 -> 5000 | N28: =$C28/$C$9 -> 5000 | O28: =$C28/$C$9 -> 5000 | R28: =COUNTIF(H28:Q28,"<>0")+2 -> 10
G29: Đánh cầu ngày 05/09
C30: 240000 | D30: =L24 -> Kiên | F30: =C30=sum(H30:Q30) -> TRUE | G30: Tiền sân cầu lông 05/09 | H30: =$C30/$C$10 -> 34285.714 | J30: =$C30/$C$10*2 -> 68571.429 | L30: =$C30/$C$10 -> 34285.714 | N30: =$C30/$C$10 -> 34285.714 | P30: =$C30/$C$10 -> 34285.714 | Q30: =$C30/$C$10 -> 34285.714 | R30: =COUNTIF(H30:Q30,"<>0")+1 -> 7
C31: =340000/12*3 -> 85000 | D31: =H24 -> Toàn | E31: 340k ~ 12 quả | F31: =C31=sum(H31:Q31) -> TRUE | G31: Tiền cầu (3 quả) 05/09 | H31: =$C31/$C$10 -> 12142.857 | J31: =$C31/$C$10*2 -> 24285.714 | L31: =$C31/$C$10 -> 12142.857 | N31: =$C31/$C$10 -> 12142.857 | P31: =$C31/$C$10 -> 12142.857 | Q31: =$C31/$C$10 -> 12142.857 | R31: =COUNTIF(H31:Q31,"<>0")+1 -> 7
G32: Đánh cầu ngày 22/08
C33: 205000 | D33: =L24 -> Kiên | F33: =C33=sum(H33:Q33) -> TRUE | G33: Tiền sân cầu lông 22/08 | H33: =$C33/$C$11 -> 25625 | I33: =$C33/$C$11*2 -> 51250 | K33: =$C33/$C$11 -> 25625 | L33: =$C33/$C$11 -> 25625 | M33: =$C33/$C$11 -> 25625 | N33: =$C33/$C$11 -> 25625 | P33: =$C33/$C$11 -> 25625 | R33: =COUNTIF(H33:Q33,"<>0")+1 -> 8
C34: =340000/C11*4 -> 170000 | D34: =H24 -> Toàn | E34: 340k ~ 12 quả | F34: =C34=sum(H34:Q34) -> TRUE | G34: Tiền cầu (4 quả) 22/08 | H34: =$C34/$C$11 -> 21250 | I34: =$C34/$C$11*2 -> 42500 | K34: =$C34/$C$11 -> 21250 | L34: =$C34/$C$11 -> 21250 | M34: =$C34/$C$11 -> 21250 | N34: =$C34/$C$11 -> 21250 | P34: =$C34/$C$11 -> 21250 | R34: =COUNTIF(H34:Q34,"<>0")+1 -> 8
G36: Bù trừ nợ đợt trước
F38: =If(C38 - round(sum(H38:Q38),0) < 5000, True, False) -> TRUE | G38: Tiền cầu lông 08/08 (xem sheet trc) | R38: =COUNTIF(H38:Q38,"<>0") -> 0
F39: =If(C39 - round(sum(H39:Q39),0) < 5000, True, False) -> TRUE | R39: =COUNTIF(H39:Q39,"<>0") -> 0
C41: DETAILS

Sheet 0808
C3: Dư nợ update tới 08/08 | G3: N.o | H3: =COLUMN(H3)-COLUMN($H$3)+1 -> 1 | I3: =COLUMN(I3)-COLUMN($H$3)+1 -> 2 | J3: =COLUMN(J3)-COLUMN($H$3)+1 -> 3 | K3: =COLUMN(K3)-COLUMN($H$3)+1 -> 4 | L3: =COLUMN(L3)-COLUMN($H$3)+1 -> 5 | M3: =COLUMN(M3)-COLUMN($H$3)+1 -> 6 | N3: =COLUMN(N3)-COLUMN($H$3)+1 -> 7 | O3: =COLUMN(O3)-COLUMN($H$3)+1 -> 8 | ... R3: =COLUMN(R3)-COLUMN($H$3)+1 -> 11
G5: Tổng kết dư nợ
G6: Cách thức: Ai có dòng màu đỏ "Chuyển tiền" chuyển khoản hết cho t theo "Tổng tiền" tương ứng phía trên, xong t sẽ chuyển lại cho những người có dòng màu xanh "Nhận tiền".
C7: Summary số lượng | M7: Outs. | N7: Outs. | O7: Outs. | P7: Outs.
C8: Số người | D8: Nội dung | G8: Thành viên | H8: Toàn | I8: Trường + Thủy | J8: Băng + Tâm | K8: Tú | L8: Kiên | M8: Thái | N8: Thảo | O8: Thanh | P8: Thanh Tâm | Q8: Thiện | R8: Quân
C9: 9 | D9: Đi cầu lông 08/08 | G9: =C22 -> Tổng ứng trước | H9: =round(sumif($D:$D,H8,$C:$C),0) -> 1308000 | I9: =round(sumif($D:$D,I8,$C:$C),0) -> 0 | J9: =round(sumif($D:$D,J8,$C:$C),0) -> 0 | K9: =round(sumif($D:$D,K8,$C:$C),0) -> 0 | L9: =round(sumif($D:$D,L8,$C:$C),0) -> 14000 | M9: =round(sumif($D:$D,M8,$C:$C),0) -> 0 | N9: =round(sumif($D:$D,N8,$C:$C),0) -> 7000 | O9: =round(sumif($D:$D,O8,$C:$C),0) -> 0 | ... R9: =round(sumif($D:$D,R8,$C:$C),0) -> 30000
C10: 6 | D10: Tốt nghiệp Diệp | G10: ="[-] "&G22 -> [-] Tổng chi phí | H10: =round(sum(H26:H41),0) -> 289741 | I10: =round(sum(I26:I41),0) -> 227259 | J10: =round(sum(J26:J41),0) -> 0 | K10: =round(sum(K26:K41),0) -> 202907 | L10: =round(sum(L26:L41),0) -> 156278 | M10: =round(sum(M26:M41),0) -> 75463 | N10: =round(sum(N26:N41),0) -> 75463 | O10: =round(sum(O26:O41),0) -> 75463 | ... R10: =round(sum(R26:R41),0) -> 151796
G11: ="[-] "&G43 -> [-] Bù trừ nợ đợt trước | H11: =Sum(H45:H55) -> -164708 | I11: =Sum(I45:I55) -> -96814.333 | J11: =Sum(J45:J55) -> -25000 | K11: =Sum(K45:K55) -> 0 | L11: =Sum(L45:L55) -> 387724.33 | M11: =Sum(M45:M55) -> 0 | N11: =Sum(N45:N55) -> 0 | O11: =Sum(O45:O55) -> 0 | ... R11: =Sum(R45:R55) -> -60000
G12: Tổng tiền thanh toán | H12: =H9-H10-H11 -> 1182967 | I12: =I9-I10-I11 -> -130444.67 | J12: =J9-J10-J11 -> 25000 | K12: =K9-K10-K11 -> -202907 | L12: =L9-L10-L11 -> -530002.33 | M12: =M9-M10-M11 -> -75463 | N12: =N9-N10-N11 -> -68463 | O12: =O9-O10-O11 -> -75463 | ... R12: =R9-R10-R11 -> -61796
G14: K/q | H14: =if(H12<0,"Chuyển tiền","Nhận tiền") -> Nhận tiền | I14: =if(I12<0,"Chuyển tiền","Nhận tiền") -> Chuyển tiền | J14: =if(J12<0,"Chuyển tiền","Nhận tiền") -> Nhận tiền | K14: =if(K12<0,"Chuyển tiền","Nhận tiền") -> Chuyển tiền | L14: =if(L12<0,"Chuyển tiền","Nhận tiền") -> Chuyển tiền | M14: =if(M12<0,"Chuyển tiền","Nhận tiền") -> Chuyển tiền | N14: =if(N12<0,"Chuyển tiền","Nhận tiền") -> Chuyển tiền | O14: =if(O12<0,"Chuyển tiền","Nhận tiền") -> Chuyển tiền | ... R14: =if(R12<0,"Chuyển tiền","Nhận tiền") -> Chuyển tiền
G16: Tình trạng thanh toán | H16: =-sum(I16:R16) -> -1144539 | I16: =-I12 -> 130444.67 | K16: =-K12 -> 202907 | L16: =-L12 -> 530002.33 | M16: =-M12 -> 75463 | N16: =-N12 -> 68463 | O16: =-O12 -> 75463 | R16: =-R12 -> 61796
G18: Dư nợ (>0: nhận lại) | H18: =H12+H16 -> 38428 | I18: =I12+I16 -> 0 | J18: =J12+J16 -> 25000 | K18: =K12+K16 -> 0 | L18: =L12+L16 -> 0 | M18: =M12+M16 -> 0 | N18: =N12+N16 -> 0 | O18: =O12+O16 -> 0 | ... R18: =R12+R16 -> 0
G19: Status | H19: =IF(AND(H18>=-3000,H18<=1000), "Done", "") | I19: =IF(AND(I18>=-3000,I18<=1000), "Done", "") -> Done | J19: =IF(AND(J18>=-3000,J18<=1000), "Done", "") | K19: =IF(AND(K18>=-3000,K18<=1000), "Done", "") -> Done | L19: =IF(AND(L18>=-3000,L18<=1000), "Done", "") -> Done | M19: =IF(AND(M18>=-3000,M18<=2000), "Done", "") -> Done | N19: =IF(AND(N18>=-3000,N18<=2000), "Done", "") -> Done | O19: =IF(AND(O18>=-3000,O18<=2000), "Done", "") -> Done | P19: =IF(AND(P18>=-3000,P18<=1000), "Done", "") | R19: =IF(AND(R18>=-3000,R18<=1000), "Done", "") -> Done
C21: Nội dung chi tiết:
C22: Tổng ứng trước | G22: Tổng chi phí
C24: Tổng tiền | D24: Ứng bởi | E24: Ghi chú | F24: Check | G24: Danh mục chi tiêu | H24: =H8 -> Toàn | I24: =I8 -> Trường + Thủy | J24: =J8 -> Băng + Tâm | K24: =K8 -> Tú | L24: =L8 -> Kiên | M24: =M8 -> Thái | N24: =N8 -> Thảo | O24: =O8 -> Thanh | ... R24: =R8 -> Quân | S24: Số người
G25: Đánh cầu ngày 08/08
C26: 200000 | D26: =H24 -> Toàn | F26: =C26=sum(H26:R26) -> TRUE | G26: Tiền sân cầu lông 08/08 | H26: =$C26/$C$9 -> 22222.222 | I26: =$C26/$C$9*2 -> 44444.444 | K26: =$C26/$C$9 -> 22222.222 | M26: =$C26/$C$9 -> 22222.222 | N26: =$C26/$C$9 -> 22222.222 | O26: =$C26/$C$9 -> 22222.222 | P26: =$C26/$C$9 -> 22222.222 | R26: =$C26/$C$9 -> 22222.222 | S26: =COUNTIF(H26:R26,"<>0")+1 -> 9
C27: =340000/12*5 -> 141666.67 | D27: =H24 -> Toàn | E27: 340k ~ 12 quả | F27: =C27=sum(H27:R27) -> TRUE | G27: Tiền cầu (5 quả) 08/08 | H27: =$C27/$C$9 -> 15740.741 | I27: =$C27/$C$9*2 -> 31481.481 | K27: =$C27/$C$9 -> 15740.741 | M27: =$C27/$C$9 -> 15740.741 | N27: =$C27/$C$9 -> 15740.741 | O27: =$C27/$C$9 -> 15740.741 | P27: =$C27/$C$9 -> 15740.741 | R27: =$C27/$C$9 -> 15740.741 | S27: =COUNTIF(H27:R27,"<>0")+1 -> 9
C28: 30000 | D28: =R24 -> Quân | F28: =C28=sum(H28:R28) -> TRUE | G28: Tiền nước Revice (2 chai) | H28: =$C28/2 -> 15000 | K28: =$C28/2 -> 15000 | S28: =COUNTIF(H28:R28,"<>0") -> 2
C29: 300000 | D29: =D27 -> Toàn | F29: =C29=sum(H29:R29) -> TRUE | G29: Tiền ăn chè + nem chua rán | H29: =$C29/8 -> 37500 | I29: =$C29/8*2 -> 75000 | K29: =$C29/8 -> 37500 | M29: =$C29/8 -> 37500 | N29: =$C29/8 -> 37500 | O29: =$C29/8 -> 37500 | R29: =$C29/8 -> 37500 | S29: =COUNTIF(H29:R29,"<>0")+1 -> 8
G30: Đánh cầu ngày 09/08
C31: 14000 | D31: =L24 -> Kiên | F31: =C31=sum(H31:R31) -> TRUE | G31: Tiền nước lọc (2 chai) | H31: =$C31/2 -> 7000 | L31: =$C31/2 -> 7000 | S31: =COUNTIF(H31:R31,"<>0") -> 2
C32: 36000 | D32: =H24 -> Toàn | F32: =C32=sum(H32:R32) -> TRUE | G32: Tiền nước Revice (3 chai) | H32: =$C32/2 -> 18000 | L32: =$C32/2 -> 18000 | S32: =COUNTIF(H32:R32,"<>0") -> 2
C33: 50000 | D33: =D32 -> Toàn | F33: =C33=sum(H33:R33) -> TRUE | G33: Tiền bánh mỳ | H33: 25000 | L33: 25000 | S33: =COUNTIF(H33:R33,"<>0") -> 2
C34: 7000 | D34: =N24 -> Thảo | F34: =C34=sum(H34:R34) -> TRUE | G34: Tiền nước (1 chai) | H34: =$C34/2 -> 3500 | L34: =$C34/2 -> 3500 | S34: =COUNTIF(H34:R34,"<>0") -> 2
G35: Tốt nghiệp Diệp
C36: 200000 | D36: =H24 -> Toàn | F36: =C36=sum(H36:R36) -> TRUE | G36: Tiền hoa cho Diệp + Matcha | H36: =$C36/$C$10 -> 33333.333 | I36: =$C36/$C$10 -> 33333.333 | K36: =$C36/$C$10 -> 33333.333 | L36: =$C36/$C$10 -> 33333.333 | Q36: =$C36/$C$10 -> 33333.333 | R36: =$C36/$C$10 -> 33333.333 | S36: =COUNTIF(H36:R36,"<>0") -> 6
C37: =sum(H37:R37) -> 172000 | D37: =H24 -> Toàn | F37: =C37=sum(H37:R37) -> TRUE | G37: Ăn bún bò huế buổi trưa | H37: 43000 | I37: 43000 | K37: 43000 | R37: 43000 | S37: =COUNTIF(H37:R37,"<>0") -> 4
C38: 100000 | D38: =H24 -> Toàn | F38: =C38=sum(H38:R38) -> TRUE | G38: Tiền đi taxi | H38: =$C38/3 -> 33333.333 | L38: =$C38/3 -> 33333.333 | Q38: =$C38/3 -> 33333.333 | S38: =COUNTIF(H38:R38,"<>0") -> 3
G39: Đánh cầu ngày 07/08
C40: 80000 | D40: =H24 -> Toàn | F40: =C40=sum(H40:R40) -> TRUE | G40: Tiền sân cầu lông 07/08 | H40: =$C40/3 -> 26666.667 | K40: =$C40/3 -> 26666.667 | L40: =$C40/3 -> 26666.667 | S40: =COUNTIF(H40:R40,"<>0") -> 3
C41: =340000/12 -> 28333.333 | D41: =D40 -> Toàn | F41: =C41=sum(H41:R41) -> TRUE | G41: Tiền cầu (1 quả) 07/08 | H41: =$C41/3 -> 9444.4444 | K41: =$C41/3 -> 9444.4444 | L41: =$C41/3 -> 9444.4444 | S41: =COUNTIF(H41:R41,"<>0") -> 3
G43: Bù trừ nợ đợt trước
F45: =If(C45 - round(sum(H45:R45),0) < 5000, True, False) -> TRUE | G45: Tiền cầu lông 01/08 (xem sheet trc) | H45: {=-_xlfn.XLOOKUP(H$24,'0108'!$8:$8,'0108'!$18:$18)} -> -281374.67 | I45: {=-_xlfn.XLOOKUP(I$24,'0108'!$8:$8,'0108'!$18:$18)} -> -20147.667 | J45: {=-_xlfn.XLOOKUP(J$24,'0108'!$8:$8,'0108'!$18:$18)} -> -25000 | L45: {=-_xlfn.XLOOKUP(L$24,'0108'!$8:$8,'0108'!$18:$18)} -> 387724.33 | R45: {=-_xlfn.XLOOKUP(R$24,'0108'!$8:$8,'0108'!$18:$18)} -> -60000 | S45: =COUNTIF(H45:R45,"<>0") -> 5
F46: =If(C46 - round(sum(H46:R46),0) < 5000, True, False) -> TRUE | G46: Thiện và Toàn | Túi ni lông | H46: 40000 | Q46: -40000 | S46: =COUNTIF(H46:R46,"<>0") -> 2
F47: =If(C47 - round(sum(H47:R47),0) < 5000, True, False) -> TRUE | G47: Toàn và Trường | Tiền điều hòa | H47: =400000/3*2 -> 266666.67 | I47: =-H47 -> -266666.67 | S47: =COUNTIF(H47:R47,"<>0") -> 2
F48: =If(C48 - round(sum(H48:R48),0) < 5000, True, False) -> TRUE | G48: Toàn và Trường | Tiền căng cước | H48: -190000 | I48: =-H48 -> 190000 | S48: =COUNTIF(H48:R48,"<>0") -> 2
C50: DETAILS

Sheet 0108
C3: Dư nợ update tới 01/08 | G3: N.o | H3: =COLUMN(H3)-COLUMN($H$3)+1 -> 1 | I3: =COLUMN(I3)-COLUMN($H$3)+1 -> 2 | J3: =COLUMN(J3)-COLUMN($H$3)+1 -> 3 | K3: =COLUMN(K3)-COLUMN($H$3)+1 -> 4 | L3: =COLUMN(L3)-COLUMN($H$3)+1 -> 5 | M3: =COLUMN(M3)-COLUMN($H$3)+1 -> 6 | N3: =COLUMN(N3)-COLUMN($H$3)+1 -> 7 | O3: =COLUMN(O3)-COLUMN($H$3)+1 -> 8
G5: Tổng kết dư nợ
G6: Cách thức: Ai có dòng màu đỏ "Chuyển tiền" chuyển khoản hết cho t theo "Tổng tiền" tương ứng phía trên, xong t sẽ chuyển lại cho những người có dòng màu xanh "Nhận tiền".
C7: Summary số lượng | L7: Outs. | M7: Outs. | N7: Outs.
C8: Số người | D8: Nội dung | G8: Thành viên | H8: Toàn | I8: Trường + Thủy | J8: Băng + Tâm | K8: Kiên | L8: Thái | M8: Thảo | N8: Phan | O8: Quân
C9: 9 | D9: Đi cầu lông 01/08 | G9: =C22 -> Tổng ứng trước | H9: =round(sumif($D:$D,H8,$C:$C),0) -> 380000 | I9: =round(sumif($D:$D,I8,$C:$C),0) -> 0 | J9: =round(sumif($D:$D,J8,$C:$C),0) -> 0 | K9: =round(sumif($D:$D,K8,$C:$C),0) -> 0 | L9: =round(sumif($D:$D,L8,$C:$C),0) -> 0 | M9: =round(sumif($D:$D,M8,$C:$C),0) -> 0 | N9: =round(sumif($D:$D,N8,$C:$C),0) -> 25000 | O9: =round(sumif($D:$D,O8,$C:$C),0) -> 0
G10: ="[-] "&G22 -> [-] Tổng chi phí | H10: =round(sum(H25:H28),0) -> 45000 | I10: =round(sum(I25:I28),0) -> 90000 | J10: =round(sum(J25:J28),0) -> 90000 | K10: =round(sum(K25:K28),0) -> 45000 | L10: =round(sum(L25:L28),0) -> 45000 | M10: =round(sum(M25:M28),0) -> 45000 | N10: =round(sum(N25:N28),0) -> 45000 | O10: =round(sum(O25:O28),0) -> 0
G11: ="[-] "&G30 -> [-] Bù trừ nợ đợt trước | H11: =Sum(H32:H41) -> -171374.67 | I11: =Sum(I32:I41) -> -110147.67 | J11: =Sum(J32:J41) -> 0 | K11: =Sum(K32:K41) -> 342724.33 | L11: =Sum(L32:L41) -> 0 | M11: =Sum(M32:M41) -> 0 | N11: =Sum(N32:N41) -> 0 | O11: =Sum(O32:O41) -> -60000
G12: Tổng tiền thanh toán | H12: =H9-H10-H11 -> 506374.67 | I12: =I9-I10-I11 -> 20147.667 | J12: =J9-J10-J11 -> -90000 | K12: =K9-K10-K11 -> -387724.33 | L12: =L9-L10-L11 -> -45000 | M12: =M9-M10-M11 -> -45000 | N12: =N9-N10-N11 -> -20000 | O12: =O9-O10-O11 -> 60000
G14: K/q | H14: =if(H12<0,"Chuyển tiền","Nhận tiền") -> Nhận tiền | I14: =if(I12<0,"Chuyển tiền","Nhận tiền") -> Nhận tiền | J14: =if(J12<0,"Chuyển tiền","Nhận tiền") -> Chuyển tiền | K14: =if(K12<0,"Chuyển tiền","Nhận tiền") -> Chuyển tiền | L14: =if(L12<0,"Chuyển tiền","Nhận tiền") -> Chuyển tiền | M14: =if(M12<0,"Chuyển tiền","Nhận tiền") -> Chuyển tiền | N14: =if(N12<0,"Chuyển tiền","Nhận tiền") -> Chuyển tiền | O14: =if(O12<0,"Chuyển tiền","Nhận tiền") -> Nhận tiền
G16: Tình trạng thanh toán | H16: =-sum(I16:O16) -> -225000 | J16: =-J12+25000 -> 115000 | L16: =-L12 -> 45000 | M16: =-M12 -> 45000 | N16: =-N12 -> 20000
G18: Dư nợ (>0: nhận lại) | H18: =H12+H16 -> 281374.67 | I18: =I12+I16 -> 20147.667 | J18: =J12+J16 -> 25000 | K18: =K12+K16 -> -387724.33 | L18: =L12+L16 -> 0 | M18: =M12+M16 -> 0 | N18: =N12+N16 -> 0 | O18: =O12+O16 -> 60000
G19: Status | H19: =IF(AND(H18>=-3000,H18<=1000), "Done", "") | I19: =IF(AND(I18>=-3000,I18<=1000), "Done", "") | J19: =IF(AND(J18>=-3000,J18<=1000), "Done", "") | K19: =IF(AND(K18>=-3000,K18<=1000), "Done", "") | L19: =IF(AND(L18>=-3000,L18<=2000), "Done", "") -> Done | M19: =IF(AND(M18>=-3000,M18<=2000), "Done", "") -> Done | N19: =IF(AND(N18>=-3000,N18<=2000), "Done", "") -> Done | O19: =IF(AND(O18>=-3000,O18<=2000), "Done", "")
C21: Nội dung chi tiết:
C22: Tổng ứng trước | G22: Tổng chi phí
C24: Tổng tiền | D24: Ứng bởi | E24: Ghi chú | F24: Check | G24: Danh mục chi tiêu | H24: =H8 -> Toàn | I24: =I8 -> Trường + Thủy | J24: =J8 -> Băng + Tâm | K24: =K8 -> Kiên | L24: =L8 -> Thái | M24: =M8 -> Thảo | N24: =N8 -> Phan | O24: =O8 -> Quân | P24: Số người
C25: 270000 | D25: =H24 -> Toàn | F25: =C25=sum(H25:O25) -> TRUE | G25: Tiền sân cầu lông 01/08 | H25: =$C25/$C$9 -> 30000 | I25: =$C25/$C$9*2 -> 60000 | J25: =$C25/$C$9*2 -> 60000 | K25: =$C25/$C$9 -> 30000 | L25: =$C25/$C$9 -> 30000 | M25: =$C25/$C$9 -> 30000 | N25: =$C25/$C$9 -> 30000 | P25: =COUNTIF(H25:O25,"<>0")+2 -> 9
C26: 25000 | D26: =H24 -> Toàn | F26: =C26=sum(H26:O26) -> TRUE | G26: 1 can trà đá | H26: =$C26/$C$9 -> 2777.7778 | I26: =$C26/$C$9*2 -> 5555.5556 | J26: =$C26/$C$9*2 -> 5555.5556 | K26: =$C26/$C$9 -> 2777.7778 | L26: =$C26/$C$9 -> 2777.7778 | M26: =$C26/$C$9 -> 2777.7778 | N26: =$C26/$C$9 -> 2777.7778 | P26: =COUNTIF(H26:O26,"<>0")+2 -> 9
C27: 25000 | D27: =N24 -> Phan | F27: =C27=sum(H27:O27) -> TRUE | G27: 1 can trà đá | H27: =$C27/$C$9 -> 2777.7778 | I27: =$C27/$C$9*2 -> 5555.5556 | J27: =$C27/$C$9*2 -> 5555.5556 | K27: =$C27/$C$9 -> 2777.7778 | L27: =$C27/$C$9 -> 2777.7778 | M27: =$C27/$C$9 -> 2777.7778 | N27: =$C27/$C$9 -> 2777.7778 | P27: =COUNTIF(H27:O27,"<>0")+2 -> 9
C28: =340000/12*3 -> 85000 | D28: =H24 -> Toàn | E28: 340k ~ 12 quả | F28: =C28=sum(H28:O28) -> TRUE | G28: Tiền cầu (3 quả) 01/08 | H28: =$C28/$C$9 -> 9444.4444 | I28: =$C28/$C$9*2 -> 18888.889 | J28: =$C28/$C$9*2 -> 18888.889 | K28: =$C28/$C$9 -> 9444.4444 | L28: =$C28/$C$9 -> 9444.4444 | M28: =$C28/$C$9 -> 9444.4444 | N28: =$C28/$C$9 -> 9444.4444 | P28: =COUNTIF(H28:O28,"<>0")+2 -> 9
G30: Bù trừ nợ đợt trước
F32: =If(C32 - round(sum(H32:O32),0) < 5000, True, False) -> TRUE | G32: Tiền cầu lông 24/07 (xem sheet trc) | H32: {=-_xlfn.XLOOKUP(H$24,'2407'!$8:$8,'2407'!$18:$18)} -> -176374.67 | I32: {=-_xlfn.XLOOKUP(I$24,'2407'!$8:$8,'2407'!$18:$18)} -> -150147.67 | K32: {=-_xlfn.XLOOKUP(K$24,'2407'!$8:$8,'2407'!$18:$18)} -> 387724.33 | O32: {=-_xlfn.XLOOKUP(O$24,'2407'!$8:$8,'2407'!$18:$18)} -> -60000 | P32: =COUNTIF(H32:O32,"<>0") -> 4
F33: =If(C33 - round(sum(H33:O33),0) < 5000, True, False) -> TRUE | G33: Kiên và Toàn | Túi cầu lông | H33: -80000 | K33: =-H33 -> 80000 | P33: =COUNTIF(H33:O33,"<>0") -> 2
F34: =If(C34 - round(sum(H34:O34),0) < 5000, True, False) -> TRUE | G34: Kiên, Toàn và Trường | Ăn tối | H34: =35000+15000+35000 -> 85000 | I34: 40000 | K34: =-H34-I34 -> -125000 | P34: =COUNTIF(H34:O34,"<>0") -> 3
C36: DETAILS

Sheet 2407
C3: Dư nợ update tới 24/07 | G3: N.o | H3: =COLUMN(H3)-COLUMN($H$3)+1 -> 1 | I3: =COLUMN(I3)-COLUMN($H$3)+1 -> 2 | J3: =COLUMN(J3)-COLUMN($H$3)+1 -> 3 | K3: =COLUMN(K3)-COLUMN($H$3)+1 -> 4 | L3: =COLUMN(L3)-COLUMN($H$3)+1 -> 5 | M3: =COLUMN(M3)-COLUMN($H$3)+1 -> 6 | N3: =COLUMN(N3)-COLUMN($H$3)+1 -> 7 | O3: =COLUMN(O3)-COLUMN($H$3)+1 -> 8 | P3: =COLUMN(P3)-COLUMN($H$3)+1 -> 9
G5: Tổng kết dư nợ
G6: Cách thức: Ai có dòng màu đỏ "Chuyển tiền" chuyển khoản hết cho t theo "Tổng tiền" tương ứng phía trên, xong t sẽ chuyển lại cho những người có dòng màu xanh "Nhận tiền".
C7: Summary số lượng | M7: Outs. | N7: Outs. | O7: Outs.
C8: Số người | D8: Nội dung | G8: Thành viên | H8: Toàn | I8: Trường + Thủy | J8: Băng + Tâm | K8: Kiên | L8: Tiến | M8: Thái | N8: Thanh | O8: Thảo | P8: Quân
C9: 9 | D9: Đi cầu lông 24/07 | G9: =C22 -> Tổng ứng trước | H9: =round(sumif($D:$D,H8,$C:$C),0) -> 470000 | I9: =round(sumif($D:$D,I8,$C:$C),0) -> 0 | J9: =round(sumif($D:$D,J8,$C:$C),0) -> 0 | K9: =round(sumif($D:$D,K8,$C:$C),0) -> 0 | L9: =round(sumif($D:$D,L8,$C:$C),0) -> 0 | M9: =round(sumif($D:$D,M8,$C:$C),0) -> 0 | N9: =round(sumif($D:$D,N8,$C:$C),0) -> 0 | O9: =round(sumif($D:$D,O8,$C:$C),0) -> 0 | P9: =round(sumif($D:$D,P8,$C:$C),0) -> 0
G10: ="[-] "&G22 -> [-] Tổng chi phí | H10: =round(sum(H25:H26),0) -> 0 | I10: =round(sum(I25:I26),0) -> 104444 | J10: =round(sum(J25:J26),0) -> 104444 | K10: =round(sum(K25:K26),0) -> 52222 | L10: =round(sum(L25:L26),0) -> 52222 | M10: =round(sum(M25:M26),0) -> 52222 | N10: =round(sum(N25:N26),0) -> 52222 | O10: =round(sum(O25:O26),0) -> 52222 | P10: =round(sum(P25:P26),0) -> 0
G11: ="[-] "&G28 -> [-] Bù trừ nợ đợt trước | H11: =Sum(H30:H39) -> -19706.667 | I11: =Sum(I30:I39) -> -254591.67 | J11: =Sum(J30:J39) -> 0 | K11: =Sum(K30:K39) -> 335502.33 | L11: =Sum(L30:L39) -> 0 | M11: =Sum(M30:M39) -> 0 | N11: =Sum(N30:N39) -> 0 | O11: =Sum(O30:O39) -> 0 | P11: =Sum(P30:P39) -> -60000
G12: Tổng tiền thanh toán | H12: =H9-H10-H11 -> 489706.67 | I12: =I9-I10-I11 -> 150147.67 | J12: =J9-J10-J11 -> -104444 | K12: =K9-K10-K11 -> -387724.33 | L12: =L9-L10-L11 -> -52222 | M12: =M9-M10-M11 -> -52222 | N12: =N9-N10-N11 -> -52222 | O12: =O9-O10-O11 -> -52222 | P12: =P9-P10-P11 -> 60000
G14: K/q | H14: =if(H12<0,"Chuyển tiền","Nhận tiền") -> Nhận tiền | I14: =if(I12<0,"Chuyển tiền","Nhận tiền") -> Nhận tiền | J14: =if(J12<0,"Chuyển tiền","Nhận tiền") -> Chuyển tiền | K14: =if(K12<0,"Chuyển tiền","Nhận tiền") -> Chuyển tiền | L14: =if(L12<0,"Chuyển tiền","Nhận tiền") -> Chuyển tiền | M14: =if(M12<0,"Chuyển tiền","Nhận tiền") -> Chuyển tiền | N14: =if(N12<0,"Chuyển tiền","Nhận tiền") -> Chuyển tiền | O14: =if(O12<0,"Chuyển tiền","Nhận tiền") -> Chuyển tiền | P14: =if(P12<0,"Chuyển tiền","Nhận tiền") -> Nhận tiền
G16: Tình trạng thanh toán | H16: =-sum(I16:P16) -> -313332 | J16: =-J12 -> 104444 | L16: =-L12 -> 52222 | M16: =-M12 -> 52222 | N16: =-N12 -> 52222 | O16: =-O12 -> 52222
G18: Dư nợ (>0: nhận lại) | H18: =H12+H16 -> 176374.67 | I18: =I12+I16 -> 150147.67 | J18: =J12+J16 -> 0 | K18: =K12+K16 -> -387724.33 | L18: =L12+L16 -> 0 | M18: =M12+M16 -> 0 | N18: =N12+N16 -> 0 | O18: =O12+O16 -> 0 | P18: =P12+P16 -> 60000
G19: Status | H19: =IF(AND(H18>=-3000,H18<=1000), "Done", "") | I19: =IF(AND(I18>=-3000,I18<=1000), "Done", "") | J19: =IF(AND(J18>=-3000,J18<=1000), "Done", "") -> Done | K19: =IF(AND(K18>=-3000,K18<=1000), "Done", "") | L19: =IF(AND(L18>=-3000,L18<=1000), "Done", "") -> Done | M19: =IF(AND(M18>=-3000,M18<=2000), "Done", "") -> Done | N19: =IF(AND(N18>=-3000,N18<=2000), "Done", "") -> Done | O19: =IF(AND(O18>=-3000,O18<=2000), "Done", "") -> Done | P19: =IF(AND(P18>=-3000,P18<=2000), "Done", "")
C21: Nội dung chi tiết:
C22: Tổng ứng trước | G22: Tổng chi phí
C24: Tổng tiền | D24: Ứng bởi | E24: Ghi chú | F24: Check | G24: Danh mục chi tiêu | H24: =H8 -> Toàn | I24: =I8 -> Trường + Thủy | J24: =J8 -> Băng + Tâm | K24: =K8 -> Kiên | L24: =L8 -> Tiến | M24: =M8 -> Thái | N24: =N8 -> Thanh | O24: =O8 -> Thảo | P24: =P8 -> Quân | Q24: Số người
C25: 300000 | D25: =H24 -> Toàn | F25: =C25=sum(H25:P25) -> TRUE | G25: Tiền sân cầu lông 24/07 | I25: =$C25/$C$9*2 -> 66666.667 | J25: =$C25/$C$9*2 -> 66666.667 | K25: =$C25/$C$9 -> 33333.333 | L25: =$C25/$C$9 -> 33333.333 | M25: =$C25/$C$9 -> 33333.333 | N25: =$C25/$C$9 -> 33333.333 | O25: =$C25/$C$9 -> 33333.333 | Q25: =COUNTIF(H25:P25,"<>0")+2 -> 9
C26: =340000/12*6 -> 170000 | D26: =H24 -> Toàn | E26: 340k ~ 12 quả | F26: =C26=sum(H26:P26) -> TRUE | G26: Tiền cầu (6 quả) 24/07 | I26: =$C26/$C$9*2 -> 37777.778 | J26: =$C26/$C$9*2 -> 37777.778 | K26: =$C26/$C$9 -> 18888.889 | L26: =$C26/$C$9 -> 18888.889 | M26: =$C26/$C$9 -> 18888.889 | N26: =$C26/$C$9 -> 18888.889 | O26: =$C26/$C$9 -> 18888.889 | Q26: =COUNTIF(H26:P26,"<>0")+2 -> 9
G28: Bù trừ nợ đợt trước
F30: =If(C30 - round(sum(H30:P30),0) < 5000, True, False) -> TRUE | G30: Tiền cầu lông 18/07 (xem sheet trc) | H30: {=-_xlfn.XLOOKUP(H$24,'1807'!$7:$7,'1807'!$17:$17)} -> 58293.333 | I30: {=-_xlfn.XLOOKUP(I$24,'1807'!$7:$7,'1807'!$17:$17)} -> -254591.67 | K30: {=-_xlfn.XLOOKUP(K$24,'1807'!$7:$7,'1807'!$17:$17)} -> 257502.33 | P30: {=-_xlfn.XLOOKUP(P$24,'1807'!$7:$7,'1807'!$17:$17)} -> -60000 | Q30: =COUNTIF(H30:P30,"<>0") -> 4
F31: =If(C31 - round(sum(H31:P31),0) < 5000, True, False) -> TRUE | G31: Kiên và Toàn | Tiền đánh cầu | H31: -28000 | K31: 28000 | Q31: =COUNTIF(H31:P31,"<>0") -> 2
F32: =If(C32 - round(sum(H32:P32),0) < 5000, True, False) -> TRUE | G32: Kiên và Toàn | Tiền ăn tối 24/07 | H32: -50000 | K32: 50000 | Q32: =COUNTIF(H32:P32,"<>0") -> 2
C34: DETAILS

Sheet 1807
C3: Dư nợ update tới 18/07 | G3: N.o | H3: =COLUMN(H3)-COLUMN($H$3)+1 -> 1 | I3: =COLUMN(I3)-COLUMN($H$3)+1 -> 2 | J3: =COLUMN(J3)-COLUMN($H$3)+1 -> 3 | K3: =COLUMN(K3)-COLUMN($H$3)+1 -> 4 | L3: =COLUMN(L3)-COLUMN($H$3)+1 -> 5 | M3: =COLUMN(M3)-COLUMN($H$3)+1 -> 6 | N3: =COLUMN(N3)-COLUMN($H$3)+1 -> 7 | O3: =COLUMN(O3)-COLUMN($H$3)+1 -> 8 | P3: =COLUMN(P3)-COLUMN($H$3)+1 -> 9
G5: Tổng kết dư nợ
G6: Cách thức: Ai có dòng màu đỏ "Chuyển tiền" chuyển khoản hết cho t theo "Tổng tiền" tương ứng phía trên, xong t sẽ chuyển lại cho những người có dòng màu xanh "Nhận tiền".
C7: Số người | D7: Nội dung | G7: Thành viên | H7: Toàn | I7: Trường + Thủy | J7: Thanh Tâm | K7: Băng + Tâm | L7: Kiên | M7: Tú | N7: Diệp | O7: Quân | P7: Tiến
C8: 7 | D8: Đi cầu lông 18/07 | G8: =C21 -> Tổng ứng trước | H8: =round(sumif($D:$D,H7,$C:$C),0) -> 383333 | I8: =round(sumif($D:$D,I7,$C:$C),0) -> 0 | J8: =round(sumif($D:$D,J7,$C:$C),0) -> 0 | K8: =round(sumif($D:$D,K7,$C:$C),0) -> 0 | L8: =round(sumif($D:$D,L7,$C:$C),0) -> 18000 | M8: =round(sumif($D:$D,M7,$C:$C),0) -> 0 | N8: =round(sumif($D:$D,N7,$C:$C),0) -> 0 | O8: =round(sumif($D:$D,O7,$C:$C),0) -> 0 | P8: =round(sumif($D:$D,P7,$C:$C),0) -> 0
G9: ="[-] "&G21 -> [-] Tổng chi phí | H9: =round(sum(H24:H26),0) -> 57762 | I9: =round(sum(I24:I26),0) -> 57762 | J9: =round(sum(J24:J26),0) -> 54762 | K9: =round(sum(K24:K26),0) -> 57762 | L9: =round(sum(L24:L26),0) -> 57762 | M9: =round(sum(M24:M26),0) -> 57762 | N9: =round(sum(N24:N26),0) -> 57762 | O9: =round(sum(O24:O26),0) -> 0 | P9: =round(sum(P24:P26),0) -> 0
G10: ="[-] "&G28 -> [-] Bù trừ nợ đợt trước | H10: =Sum(H30:H39) -> 45884.333 | I10: =Sum(I30:I39) -> -312353.67 | J10: =Sum(J30:J39) -> 75000 | K10: =Sum(K30:K39) -> 0 | L10: =Sum(L30:L39) -> 217740.33 | M10: =Sum(M30:M39) -> 0 | N10: =Sum(N30:N39) -> 0 | O10: =Sum(O30:O39) -> -60000 | P10: =Sum(P30:P39) -> 34932
G11: Tổng tiền thanh toán | H11: =H8-H9-H10 -> 279686.67 | I11: =I8-I9-I10 -> 254591.67 | J11: =J8-J9-J10 -> -129762 | K11: =K8-K9-K10 -> -57762 | L11: =L8-L9-L10 -> -257502.33 | M11: =M8-M9-M10 -> -57762 | N11: =N8-N9-N10 -> -57762 | O11: =O8-O9-O10 -> 60000 | P11: =P8-P9-P10 -> -34932
G13: K/q | H13: =if(H11<0,"Chuyển tiền","Nhận tiền") -> Nhận tiền | I13: =if(I11<0,"Chuyển tiền","Nhận tiền") -> Nhận tiền | J13: =if(J11<0,"Chuyển tiền","Nhận tiền") -> Chuyển tiền | K13: =if(K11<0,"Chuyển tiền","Nhận tiền") -> Chuyển tiền | L13: =if(L11<0,"Chuyển tiền","Nhận tiền") -> Chuyển tiền | M13: =if(M11<0,"Chuyển tiền","Nhận tiền") -> Chuyển tiền | N13: =if(N11<0,"Chuyển tiền","Nhận tiền") -> Chuyển tiền | O13: =if(O11<0,"Chuyển tiền","Nhận tiền") -> Nhận tiền | P13: =if(P11<0,"Chuyển tiền","Nhận tiền") -> Chuyển tiền
G15: Tình trạng thanh toán | H15: =-sum(I15:P15) -> -337980 | J15: 129762 | K15: =-K11 -> 57762 | M15: =-M11 -> 57762 | N15: =-N11 -> 57762 | P15: =-P11 -> 34932
G17: Dư nợ (>0: nhận lại) | H17: =H11+H15 -> -58293.333 | I17: =I11+I15 -> 254591.67 | J17: =J11+J15 -> 0 | K17: =K11+K15 -> 0 | L17: =L11+L15 -> -257502.33 | M17: =M11+M15 -> 0 | N17: =N11+N15 -> 0 | O17: =O11+O15 -> 60000 | P17: =P11+P15 -> 0
G18: Status | H18: =IF(AND(H17>=-3000,H17<=1000), "Done", "") | I18: =IF(AND(I17>=-3000,I17<=1000), "Done", "") | J18: =IF(AND(J17>=-3000,J17<=1000), "Done", "") -> Done | K18: =IF(AND(K17>=-3000,K17<=1000), "Done", "") -> Done | L18: =IF(AND(L17>=-3000,L17<=1000), "Done", "") | M18: =IF(AND(M17>=-3000,M17<=2000), "Done", "") -> Done | N18: =IF(AND(N17>=-3000,N17<=2000), "Done", "") -> Done | O18: =IF(AND(O17>=-3000,O17<=2000), "Done", "") | P18: =IF(AND(P17>=-3000,P17<=2000), "Done", "") -> Done
C20: Nội dung chi tiết:
C21: Tổng ứng trước | G21: Tổng chi phí
C23: Tổng tiền | D23: Ứng bởi | E23: Ghi chú | F23: Check | G23: Danh mục chi tiêu | H23: =H7 -> Toàn | I23: =I7 -> Trường + Thủy | J23: =J7 -> Thanh Tâm | K23: =K7 -> Băng + Tâm | L23: =L7 -> Kiên | M23: =M7 -> Tú | N23: =N7 -> Diệp | O23: =O7 -> Quân | P23: =P7 -> Tiến | Q23: Số người
C24: 270000 | D24: =H23 -> Toàn | F24: =C24=sum(H24:P24) -> TRUE | G24: Tiền sân cầu lông 18/07 | H24: =$C24/$C$8 -> 38571.429 | I24: =$C24/$C$8 -> 38571.429 | J24: =$C24/$C$8 -> 38571.429 | K24: =$C24/$C$8 -> 38571.429 | L24: =$C24/$C$8 -> 38571.429 | M24: =$C24/$C$8 -> 38571.429 | N24: =$C24/$C$8 -> 38571.429 | Q24: =COUNTIF(H24:P24,"<>0") -> 7
C25: =340000/12*4 -> 113333.33 | D25: =H23 -> Toàn | E25: 340k ~ 12 quả | F25: =C25=sum(H25:P25) -> TRUE | G25: Tiền cầu ( quả) 18/07 | H25: =$C25/$C$8 -> 16190.476 | I25: =$C25/$C$8 -> 16190.476 | J25: =$C25/$C$8 -> 16190.476 | K25: =$C25/$C$8 -> 16190.476 | L25: =$C25/$C$8 -> 16190.476 | M25: =$C25/$C$8 -> 16190.476 | N25: =$C25/$C$8 -> 16190.476 | Q25: =COUNTIF(H25:P25,"<>0") -> 7
C26: 18000 | D26: =L23 -> Kiên | E26: 9k ~ 1 chai | F26: =C26=sum(H26:P26) -> TRUE | G26: Tiền nước Revice (2 chai) | H26: =$C26/($C$8-1) -> 3000 | I26: =$C26/($C$8-1) -> 3000 | K26: =$C26/($C$8-1) -> 3000 | L26: =$C26/($C$8-1) -> 3000 | M26: =$C26/($C$8-1) -> 3000 | N26: =$C26/($C$8-1) -> 3000 | Q26: =COUNTIF(H26:P26,"<>0") -> 6
G28: Bù trừ nợ đợt trước
F30: =If(C30 - round(sum(H30:P30),0) < 5000, True, False) -> TRUE | G30: Tiền cầu lông 11/07 (xem sheet trc) | H30: {=-_xlfn.XLOOKUP(H$23,'1107'!$7:$7,'1107'!$17:$17)} -> 310884.33 | I30: {=-_xlfn.XLOOKUP(I$23,'1107'!$7:$7,'1107'!$17:$17)} -> -312353.67 | L30: {=-_xlfn.XLOOKUP(L$23,'1107'!$7:$7,'1107'!$17:$17)} -> 27740.333 | O30: {=-_xlfn.XLOOKUP(O$23,'1107'!$7:$7,'1107'!$17:$17)} -> -60000 | P30: {=-_xlfn.XLOOKUP(P$23,'1107'!$7:$7,'1107'!$17:$17)} -> 34932 | Q30: =COUNTIF(H30:P30,"<>0") -> 5
F31: =If(C31 - round(sum(H31:P31),0) < 5000, True, False) -> TRUE | G31: Tâm và Toàn | Tiền ăn tối | H31: -75000 | J31: =-H31 -> 75000 | Q31: =COUNTIF(H31:P31,"<>0") -> 2
F32: =If(C32 - round(sum(H32:P32),0) < 5000, True, False) -> TRUE | G32: Kiên và Toàn | Tiền sửa xe | H32: -190000 | L32: =-H32 -> 190000 | Q32: =COUNTIF(H32:P32,"<>0") -> 2
C34: DETAILS

Sheet 1107
C3: Dư nợ update tới 11/07 | G3: N.o | H3: 1 | I3: =H3+1 -> 2 | J3: =I3+1 -> 3 | K3: =J3+1 -> 4 | L3: =K3+1 -> 5 | M3: =L3+1 -> 6 | N3: 7 | O3: 8 | P3: =O3+1 -> 9
G5: Tổng kết dư nợ
G6: Cách thức: Ai có dòng màu đỏ "Chuyển tiền" chuyển khoản hết cho t theo "Tổng tiền" tương ứng phía trên, xong t sẽ chuyển lại cho những người có dòng màu xanh "Nhận tiền".
C7: Số người | D7: Nội dung | G7: Thành viên | H7: Toàn | I7: Trường + Thủy | J7: Thanh Tâm | K7: Băng + Tâm | L7: Kiên | M7: Tú | N7: Khiêm | O7: Quân | P7: Tiến
C8: 9 | D8: Đi cầu lông 11/07 | G8: =C21 -> Tổng ứng trước | H8: =round(sumif($D:$D,H7,$C:$C),0) -> 714667 | I8: =round(sumif($D:$D,I7,$C:$C),0) -> 0 | J8: =round(sumif($D:$D,J7,$C:$C),0) -> 0 | K8: =round(sumif($D:$D,K7,$C:$C),0) -> 0 | L8: =round(sumif($D:$D,L7,$C:$C),0) -> 27000 | M8: =round(sumif($D:$D,M7,$C:$C),0) -> 0 | N8: =round(sumif($D:$D,N7,$C:$C),0) -> 0 | O8: =round(sumif($D:$D,O7,$C:$C),0) -> 0 | P8: =round(sumif($D:$D,P7,$C:$C),0) -> 0
G9: ="[-] "&G21 -> [-] Tổng chi phí | H9: =round(sum(H24:H29),0) -> 95503 | I9: =round(sum(I24:I29),0) -> 85503 | J9: =round(sum(J24:J29),0) -> 54074 | K9: =round(sum(K24:K29),0) -> 164577 | L9: =round(sum(L24:L29),0) -> 85503 | M9: =round(sum(M24:M29),0) -> 85503 | N9: =round(sum(N24:N29),0) -> 85503 | O9: =round(sum(O24:O29),0) -> 0 | P9: =round(sum(P24:P29),0) -> 85503
G10: ="[-] "&G31 -> [-] Bù trừ nợ đợt trước | H10: =Sum(H33:H45) -> 541023.33 | I10: =Sum(I33:I45) -> -397856.67 | J10: =Sum(J33:J45) -> 0 | K10: =Sum(K33:K45) -> 464 | L10: =Sum(L33:L45) -> -30762.667 | M10: =Sum(M33:M45) -> -1096 | N10: =Sum(N33:N45) -> 0 | O10: =Sum(O33:O45) -> -60000 | P10: =Sum(P33:P45) -> -50571
G11: Tổng tiền thanh toán | H11: =H8-H9-H10 -> 78140.667 | I11: =I8-I9-I10 -> 312353.67 | J11: =J8-J9-J10 -> -54074 | K11: =K8-K9-K10 -> -165041 | L11: =L8-L9-L10 -> -27740.333 | M11: =M8-M9-M10 -> -84407 | N11: =N8-N9-N10 -> -85503 | O11: =O8-O9-O10 -> 60000 | P11: =P8-P9-P10 -> -34932
G13: K/q | H13: =if(H11<0,"Chuyển tiền","Nhận tiền") -> Nhận tiền | I13: =if(I11<0,"Chuyển tiền","Nhận tiền") -> Nhận tiền | J13: =if(J11<0,"Chuyển tiền","Nhận tiền") -> Chuyển tiền | K13: =if(K11<0,"Chuyển tiền","Nhận tiền") -> Chuyển tiền | L13: =if(L11<0,"Chuyển tiền","Nhận tiền") -> Chuyển tiền | M13: =if(M11<0,"Chuyển tiền","Nhận tiền") -> Chuyển tiền | N13: =if(N11<0,"Chuyển tiền","Nhận tiền") -> Chuyển tiền | O13: =if(O11<0,"Chuyển tiền","Nhận tiền") -> Nhận tiền | P13: =if(P11<0,"Chuyển tiền","Nhận tiền") -> Chuyển tiền
G15: Tình trạng thanh toán | H15: =-sum(I15:P15) -> -389025 | J15: 54074 | K15: 165041 | M15: =84407 -> 84407 | N15: 85503
G17: Dư nợ (>0: nhận lại) | H17: =H11+H15 -> -310884.33 | I17: =I11+I15 -> 312353.67 | J17: =J11+J15 -> 0 | K17: =K11+K15 -> 0 | L17: =L11+L15 -> -27740.333 | M17: =M11+M15 -> 0 | N17: =N11+N15 -> 0 | O17: =O11+O15 -> 60000 | P17: =P11+P15 -> -34932
G18: Status | H18: =IF(AND(H17>=-3000,H17<=1000), "Done", "") | I18: =IF(AND(I17>=-3000,I17<=1000), "Done", "") | J18: =IF(AND(J17>=-3000,J17<=1000), "Done", "") -> Done | K18: =IF(AND(K17>=-3000,K17<=1000), "Done", "") -> Done | L18: =IF(AND(L17>=-3000,L17<=1000), "Done", "") | M18: =IF(AND(M17>=-3000,M17<=2000), "Done", "") -> Done | N18: =IF(AND(N17>=-3000,N17<=2000), "Done", "") -> Done | O18: =IF(AND(O17>=-3000,O17<=2000), "Done", "") | P18: =IF(AND(P17>=-3000,P17<=2000), "Done", "")
C20: Nội dung chi tiết:
C21: Tổng ứng trước | G21: Tổng chi phí
C23: Tổng tiền | D23: Ứng bởi | E23: Ghi chú | F23: Check | G23: Danh mục chi tiêu | H23: =H7 -> Toàn | I23: =I7 -> Trường + Thủy | J23: =J7 -> Thanh Tâm | K23: =K7 -> Băng + Tâm | L23: =L7 -> Kiên | M23: =M7 -> Tú | N23: =N7 -> Khiêm | O23: =O7 -> Quân | P23: =P7 -> Tiến | Q23: Số người
C24: =270000+75000 -> 345000 | D24: =H23 -> Toàn | F24: =C24=sum(H24:P24) -> TRUE | G24: Tiền sân cầu lông 11/07 | H24: =$C24/$C$8 -> 38333.333 | I24: =$C24/$C$8 -> 38333.333 | J24: =$C24/$C$8 -> 38333.333 | K24: =$C24/$C$8*2 -> 76666.667 | L24: =$C24/$C$8 -> 38333.333 | M24: =$C24/$C$8 -> 38333.333 | N24: =$C24/$C$8 -> 38333.333 | P24: =$C24/$C$8 -> 38333.333 | Q24: =COUNTIF(H24:P24,"<>0")+1 -> 9
C25: =340000/12*5 -> 141666.67 | D25: =H23 -> Toàn | E25: 340k ~ 12 quả | F25: =C25=sum(H25:P25) -> TRUE | G25: Tiền cầu (5 quả) 11/07 | H25: =$C25/$C$8 -> 15740.741 | I25: =$C25/$C$8 -> 15740.741 | J25: =$C25/$C$8 -> 15740.741 | K25: =$C25/$C$8*2 -> 31481.481 | L25: =$C25/$C$8 -> 15740.741 | M25: =$C25/$C$8 -> 15740.741 | N25: =$C25/$C$8 -> 15740.741 | P25: =$C25/$C$8 -> 15740.741 | Q25: =COUNTIF(H25:P25,"<>0")+1 -> 9
C26: 18000 | D26: =H23 -> Toàn | E26: 9k ~ 1 chai | F26: =C26=sum(H26:P26) -> TRUE | G26: Tiền nước Revice (2 chai) | H26: =$C26/($C$8-2) -> 2571.4286 | I26: =$C26/($C$8-2) -> 2571.4286 | K26: =$C26/($C$8-2) -> 2571.4286 | L26: =$C26/($C$8-2) -> 2571.4286 | M26: =$C26/($C$8-2) -> 2571.4286 | N26: =$C26/($C$8-2) -> 2571.4286 | P26: =$C26/($C$8-2) -> 2571.4286 | Q26: =COUNTIF(H26:P26,"<>0") -> 7
C27: 27000 | D27: =L23 -> Kiên | E27: 9k ~ 1 chai | G27: Tiền nước Revice (3 chai) | H27: =$C27/($C$8-2) -> 3857.1429 | I27: =$C27/($C$8-2) -> 3857.1429 | K27: =$C27/($C$8-2) -> 3857.1429 | L27: =$C27/($C$8-2) -> 3857.1429 | M27: =$C27/($C$8-2) -> 3857.1429 | N27: =$C27/($C$8-2) -> 3857.1429 | P27: =$C27/($C$8-2) -> 3857.1429 | Q27: =COUNTIF(H27:P27,"<>0") -> 7
C29: 210000 | D29: =H23 -> Toàn | F29: =C29=sum(H29:P29) -> TRUE | G29: Tiền nước CV Phùng Khoang | H29: =210000-I29-K29-L29-M29-N29-P29 -> 35000 | I29: 25000 | K29: 50000 | L29: 25000 | M29: 25000 | N29: 25000 | P29: 25000 | Q29: =COUNTIF(H29:P29,"<>0") -> 7
G31: Bù trừ nợ đợt trước
F33: =If(C33 - round(sum(H33:P33),0) < 5000, True, False) -> TRUE | G33: Tiền cầu lông 04/07 (xem sheet trc) | H33: =-'0407'!H17 -> 316190 | I33: =-'0407'!I17 -> -74940 | K33: =-'0407'!K17 -> 464 | L33: =-'0407'!L17 -> -128846 | M33: =-'0407'!M17 -> -1096 | O33: =-'0407'!O17 -> -60000 | P33: =-'2606'!N17 -> -50571 | Q33: =COUNTIF(H33:P33,"<>0") -> 7
F34: =If(C34 - round(sum(H34:P34),0) < 5000, True, False) -> TRUE | G34: Kiên và Toàn | Tiền cơm rang ăn tối | H34: -45000 | L34: =-H34 -> 45000 | Q34: =COUNTIF(H34:P34,"<>0") -> 2
F35: =If(C35 - round(sum(H35:P35),0) < 5000, True, False) -> TRUE | G35: Kiên, Toàn và Trường | Tiền cầu lông | H35: =-99250/3*2 -> -66166.667 | I35: =-H35/2 -> 33083.333 | L35: =-H35/2 -> 33083.333 | Q35: =COUNTIF(H35:P35,"<>0") -> 3
F36: =If(C36 - round(sum(H36:P36),0) < 5000, True, False) -> TRUE | G36: Kiên và Toàn | Tiền sửa xe | H36: -20000 | L36: 20000
F37: =If(C37 - round(sum(H37:P37),0) < 5000, True, False) -> TRUE | G37: Toàn và Trường | Băng chuyển nhầm | H37: 178000 | I37: -178000
F38: =If(C38 - round(sum(H38:P38),0) < 5000, True, False) -> TRUE | G38: Toàn và Trường | Tiền ăn nướng trưa CN | H38: 178000 | I38: =-H38 -> -178000 | Q38: =COUNTIF(H38:P38,"<>0") -> 2
C40: DETAILS

Sheet 0407
C3: Dư nợ update tới 04/07 | G3: N.o | H3: 1 | I3: =H3+1 -> 2 | J3: =I3+1 -> 3 | K3: =J3+1 -> 4 | L3: =K3+1 -> 5 | M3: =L3+1 -> 6 | N3: 7 | O3: 8 | P3: =O3+1 -> 9
G5: Tổng kết dư nợ
G6: Cách thức: Ai có dòng màu đỏ "Chuyển tiền" chuyển khoản hết cho t theo "Tổng tiền" tương ứng phía trên, xong t sẽ chuyển lại cho những người có dòng màu xanh "Nhận tiền".
C7: Số người | D7: Nội dung | G7: Thành viên | H7: Toàn | I7: Trường | J7: Thanh Tâm | K7: Băng + Tâm | L7: Kiên | M7: Tú | N7: Dũng | O7: Quân | P7: Tiến
C8: 7 | D8: Đi cầu lông 04/07 | G8: =C21 -> Tổng ứng trước | H8: =round(sumif($D:$D,H7,$C:$C),0) -> 386333 | I8: =round(sumif($D:$D,I7,$C:$C),0) -> 0 | J8: =round(sumif($D:$D,J7,$C:$C),0) -> 0 | K8: =round(sumif($D:$D,K7,$C:$C),0) -> 0 | L8: =round(sumif($D:$D,L7,$C:$C),0) -> 160000 | M8: =round(sumif($D:$D,M7,$C:$C),0) -> 0 | N8: =round(sumif($D:$D,N7,$C:$C),0) -> 0 | O8: =round(sumif($D:$D,O7,$C:$C),0) -> 0 | P8: =round(sumif($D:$D,P7,$C:$C),0) -> 0
C9: 4 | D9: Đi cầu lông 26/07 | G9: ="[-] "&G21 -> [-] Tổng chi phí | H9: =round(sum(H24:H30),0) -> 101190 | I9: =round(sum(I24:I30),0) -> 48667 | J9: =round(sum(J24:J30),0) -> 44524 | K9: =round(sum(K24:K30),0) -> 97048 | L9: =round(sum(L24:L30),0) -> 101190 | M9: =round(sum(M24:M30),0) -> 101190 | N9: =round(sum(N24:N30),0) -> 52524 | O9: =round(sum(O24:O30),0) -> 0 | P9: =round(sum(P24:P30),0) -> 0
G10: ="[-] "&G32 -> [-] Bù trừ nợ đợt trước | H10: =Sum(H34:H48) -> 118285 | I10: =Sum(I34:I48) -> -123607 | J10: =Sum(J34:J48) -> 40000 | K10: =Sum(K34:K48) -> -584 | L10: =Sum(L34:L48) -> -70036 | M10: =Sum(M34:M48) -> 147714 | N10: =Sum(N34:N48) -> 0 | O10: =Sum(O34:O48) -> -60000 | P10: =Sum(P34:P48) -> -50571
G11: Tổng tiền thanh toán | H11: =H8-H9-H10 -> 166858 | I11: =I8-I9-I10 -> 74940 | J11: =J8-J9-J10 -> -84524 | K11: =K8-K9-K10 -> -96464 | L11: =L8-L9-L10 -> 128846 | M11: =M8-M9-M10 -> -248904 | N11: =N8-N9-N10 -> -52524 | O11: =O8-O9-O10 -> 60000 | P11: =P8-P9-P10 -> 50571
G13: K/q | H13: =if(H11<0,"Chuyển tiền","Nhận tiền") -> Nhận tiền | I13: =if(I11<0,"Chuyển tiền","Nhận tiền") -> Nhận tiền | J13: =if(J11<0,"Chuyển tiền","Nhận tiền") -> Chuyển tiền | K13: =if(K11<0,"Chuyển tiền","Nhận tiền") -> Chuyển tiền | L13: =if(L11<0,"Chuyển tiền","Nhận tiền") -> Nhận tiền | M13: =if(M11<0,"Chuyển tiền","Nhận tiền") -> Chuyển tiền | N13: =if(N11<0,"Chuyển tiền","Nhận tiền") -> Chuyển tiền | O13: =if(O11<0,"Chuyển tiền","Nhận tiền") -> Nhận tiền | P13: =if(P11<0,"Chuyển tiền","Nhận tiền") -> Nhận tiền
G15: Tình trạng thanh toán | H15: =-sum(I15:P15) -> -483048 | J15: 84524 | K15: 96000 | M15: 250000 | N15: 52524
G17: Dư nợ | H17: =H11+H15 -> -316190 | I17: =I11+I15 -> 74940 | J17: =J11+J15 -> 0 | K17: =K11+K15 -> -464 | L17: =L11+L15 -> 128846 | M17: =M11+M15 -> 1096 | N17: =N11+N15 -> 0 | O17: =O11+O15 -> 60000 | P17: =P11+P15 -> 50571
G18: Status | H18: =IF(AND(H17>=-3000,H17<=1000), "Done", "") | I18: =IF(AND(I17>=-3000,I17<=1000), "Done", "") | J18: =IF(AND(J17>=-3000,J17<=1000), "Done", "") -> Done | K18: =IF(AND(K17>=-3000,K17<=1000), "Done", "") -> Done | L18: =IF(AND(L17>=-3000,L17<=1000), "Done", "") | M18: =IF(AND(M17>=-3000,M17<=2000), "Done", "") -> Done | N18: =IF(AND(N17>=-3000,N17<=2000), "Done", "") -> Done | O18: =IF(AND(O17>=-3000,O17<=2000), "Done", "") | P18: =IF(AND(P17>=-3000,P17<=2000), "Done", "")
C20: Nội dung chi tiết:
C21: Tổng ứng trước | G21: Tổng chi phí
C23: Tổng tiền | D23: Ứng bởi | E23: Ghi chú | F23: Check | G23: Danh mục chi tiêu | H23: =H7 -> Toàn | I23: =I7 -> Trường | J23: =J7 -> Thanh Tâm | K23: =K7 -> Băng + Tâm | L23: =L7 -> Kiên | M23: =M7 -> Tú | N23: =N7 -> Dũng | O23: =O7 -> Quân | P23: =P7 -> Tiến | Q23: Số người
C24: 255000 | D24: =H23 -> Toàn | F24: =C24=sum(H24:P24) -> TRUE | G24: Tiền sân cầu lông 04/07 | H24: =$C24/$C$8 -> 36428.571 | J24: =$C24/$C$8 -> 36428.571 | K24: =$C24/$C$8*2 -> 72857.143 | L24: =$C24/$C$8 -> 36428.571 | M24: =$C24/$C$8 -> 36428.571 | N24: =$C24/$C$8 -> 36428.571 | Q24: =COUNTIF(H24:P24,"<>0")+1 -> 7
C25: =340000/12*2 -> 56666.667 | D25: =H23 -> Toàn | E25: 340k ~ 12 quả | F25: =C25=sum(H25:P25) -> TRUE | G25: Tiền cầu (2 quả) 04/07 | H25: =$C25/$C$8 -> 8095.2381 | J25: =$C25/$C$8 -> 8095.2381 | K25: =$C25/$C$8*2 -> 16190.476 | L25: =$C25/$C$8 -> 8095.2381 | M25: =$C25/$C$8 -> 8095.2381 | N25: =$C25/$C$8 -> 8095.2381 | Q25: =COUNTIF(H25:P25,"<>0")+1 -> 7
C26: 40000 | D26: =L23 -> Kiên | E26: 10k ~ 1 chai | F26: =C26=sum(H26:P26) -> TRUE | G26: Tiền nước Revice (4 chai) + đá | H26: =$C$26/5 -> 8000 | K26: =$C$26/5 -> 8000 | L26: =$C$26/5 -> 8000 | M26: =$C$26/5 -> 8000 | N26: =$C$26/5 -> 8000 | Q26: =COUNTIF(H26:P26,"<>0")+1 -> 6
C28: 120000 | D28: =L23 -> Kiên | F28: =C28=sum(H28:P28) -> TRUE | G28: Tiền sân cầu lông 01/07 | H28: =$C$28/$C$9 -> 30000 | I28: =$C$28/$C$9 -> 30000 | L28: =$C$28/$C$9 -> 30000 | M28: =$C$28/$C$9 -> 30000 | Q28: =COUNTIF(H28:P28,"<>0") -> 4
C29: =340000/12*2 -> 56666.667 | D29: =H23 -> Toàn | F29: =C29=sum(H29:P29) -> TRUE | G29: Tiền cầu (2 quả) 01/07 | H29: =$C$29/$C$9 -> 14166.667 | I29: =$C$29/$C$9 -> 14166.667 | L29: =$C$29/$C$9 -> 14166.667 | M29: =$C$29/$C$9 -> 14166.667 | Q29: =COUNTIF(H29:P29,"<>0") -> 4
C30: =9000*2 -> 18000 | D30: =H23 -> Toàn | E30: 9k ~ 1 chai | F30: =C30=sum(H30:P30) -> TRUE | G30: Tiền nước Revice (2 chai) | H30: =$C$30/$C$9 -> 4500 | I30: =$C$30/$C$9 -> 4500 | L30: =$C$30/$C$9 -> 4500 | M30: =$C$30/$C$9 -> 4500 | Q30: =COUNTIF(H30:P30,"<>0") -> 4
G32: Bù trừ nợ đợt trước
F34: =If(C34 - round(sum(H34:P34),0) < 5000, True, False) -> TRUE | G34: Tiền cầu lông 26/06 (xem sheet trc) | H34: =-'2606'!H17 -> 161285 | I34: =-'2606'!I17 -> -153607 | K34: =-'2606'!K17 -> -584 | L34: =-'2606'!L17 -> -8036 | M34: =-'2606'!M17 -> 52714 | P34: =-'2606'!N17 -> -50571 | Q34: =COUNTIF(H34:P34,"<>0") -> 6
F35: =If(C35 - round(sum(H35:P35),0) < 5000, True, False) -> TRUE | G35: Toàn và Tâm | Tiền ăn phở | H35: -40000 | J35: 40000
F36: =If(C36 - round(sum(H36:P36),0) < 5000, True, False) -> TRUE | G36: Kiên và Toàn | Bún bò huế ăn sáng | H36: -43000 | L36: 43000
F37: =If(C37 - round(sum(H37:P37),0) < 5000, True, False) -> TRUE | G37: Kiên và Toàn | Tiền nước cl trưa t7 | H37: 25000 | L37: -25000
F38: =If(C38 - round(sum(H38:P38),0) < 5000, True, False) -> TRUE | G38: Toàn và Tú | Tiền nước cl trưa t7 | H38: -15000 | M38: =15000 -> 15000
F39: =If(C39 - round(sum(H39:P39),0) < 5000, True, False) -> TRUE | G39: Kiền và Tú | Tiền bánh mỳ | L39: -50000 | M39: 50000
F40: =If(C40 - round(sum(H40:P40),0) < 5000, True, False) -> TRUE | G40: Tú, Trường và Quân | Tiền bún | I40: 30000 | M40: 30000 | O40: -60000 | Q40: =COUNTIF(H40:P40,"<>0") -> 3
F41: =If(C41 - round(sum(H41:P41),0) < 5000, True, False) -> TRUE | G41: Kiên và Toàn | Tiền ăn tối | H41: 30000 | L41: -30000 | Q41: =COUNTIF(H41:P41,"<>0") -> 2
C43: DETAILS

Sheet 2606
C3: Dư nợ update tới 26/06 | G3: N.o | H3: 1 | I3: =H3+1 -> 2 | J3: =I3+1 -> 3 | K3: =J3+1 -> 4 | L3: =K3+1 -> 5 | M3: =L3+1 -> 6 | N3: =M3+1 -> 7
G5: Tổng kết dư nợ
G6: Cách thức: Ai có dòng màu đỏ "Chuyển tiền" chuyển khoản hết cho t theo "Tổng tiền" tương ứng phía trên, xong t sẽ chuyển lại cho những người có dòng màu xanh "Nhận tiền".
C7: Số người | D7: Nội dung | G7: Thành viên | H7: Toàn | I7: Trường + Thủy | J7: Quân | K7: Băng + Tâm | L7: Kiên | M7: Tú | N7: Tiến
